<?xml version="1.0" ?>
<robot name="dog_assembly" xmlns:xacro="http://www.ros.org/wiki/xacro">

<xacro:include filename="$(find dog_assembly_description)/urdf/materials.xacro" />
<xacro:include filename="$(find dog_assembly_description)/urdf/dog_assembly.trans" />
<xacro:include filename="$(find dog_assembly_description)/urdf/dog_assembly.gazebo" />
<link name="base_link">
  <inertial>
    <origin xyz="-0.0005830294128865784 1.3645027639924189e-05 0.015980815837782218" rpy="0 0 0"/>
    <mass value="0.0654122809057055"/>
    <inertia ixx="5.6e-05" iyy="3.1e-05" izz="7.3e-05" ixy="0.0" iyz="0.0" ixz="0.0"/>
  </inertial>
  <visual>
    <origin xyz="0 0 0" rpy="0 0 0"/>
    <geometry>
      <mesh filename="package://dog_assembly_description/meshes/base_link.stl" scale="0.001 0.001 0.001"/>
    </geometry>
    <material name="silver"/>
  </visual>
  <collision>
    <origin xyz="0 0 0" rpy="0 0 0"/>
    <geometry>
      <mesh filename="package://dog_assembly_description/meshes/base_link.stl" scale="0.001 0.001 0.001"/>
    </geometry>
  </collision>
</link>

<link name="hip_L_simple_v2_1">
  <inertial>
    <origin xyz="0.0026469377652367614 0.00815492666919019 0.00602136608265076" rpy="0 0 0"/>
    <mass value="0.010651772434958885"/>
    <inertia ixx="1e-06" iyy="1e-06" izz="1e-06" ixy="0.0" iyz="0.0" ixz="-0.0"/>
  </inertial>
  <visual>
    <origin xyz="0.023078 -0.051162 -0.012223" rpy="0 0 0"/>
    <geometry>
      <mesh filename="package://dog_assembly_description/meshes/hip_L_simple_v2_1.stl" scale="0.001 0.001 0.001"/>
    </geometry>
    <material name="silver"/>
  </visual>
  <collision>
    <origin xyz="0.023078 -0.051162 -0.012223" rpy="0 0 0"/>
    <geometry>
      <mesh filename="package://dog_assembly_description/meshes/hip_L_simple_v2_1.stl" scale="0.001 0.001 0.001"/>
    </geometry>
  </collision>
</link>

<link name="hip_L_simple_v1_Mirror___1__1">
  <inertial>
    <origin xyz="-0.0026469632642493746 0.008154926656354214 0.006021379483711616" rpy="0 0 0"/>
    <mass value="0.010651772367412023"/>
    <inertia ixx="1e-06" iyy="1e-06" izz="1e-06" ixy="-0.0" iyz="0.0" ixz="0.0"/>
  </inertial>
  <visual>
    <origin xyz="-0.021962 -0.051162 -0.012156" rpy="0 0 0"/>
    <geometry>
      <mesh filename="package://dog_assembly_description/meshes/hip_L_simple_v1_Mirror___1__1.stl" scale="0.001 0.001 0.001"/>
    </geometry>
    <material name="silver"/>
  </visual>
  <collision>
    <origin xyz="-0.021962 -0.051162 -0.012156" rpy="0 0 0"/>
    <geometry>
      <mesh filename="package://dog_assembly_description/meshes/hip_L_simple_v1_Mirror___1__1.stl" scale="0.001 0.001 0.001"/>
    </geometry>
  </collision>
</link>

<link name="hip_L_simple_v1_Mirror__Mirror__1">
  <inertial>
    <origin xyz="-0.002646963169021202 -0.008154926669190196 0.006021378784542997" rpy="0 0 0"/>
    <mass value="0.010651772434958885"/>
    <inertia ixx="1e-06" iyy="1e-06" izz="1e-06" ixy="0.0" iyz="-0.0" ixz="0.0"/>
  </inertial>
  <visual>
    <origin xyz="-0.021962 0.051162 -0.012156" rpy="0 0 0"/>
    <geometry>
      <mesh filename="package://dog_assembly_description/meshes/hip_L_simple_v1_Mirror__Mirror__1.stl" scale="0.001 0.001 0.001"/>
    </geometry>
    <material name="silver"/>
  </visual>
  <collision>
    <origin xyz="-0.021962 0.051162 -0.012156" rpy="0 0 0"/>
    <geometry>
      <mesh filename="package://dog_assembly_description/meshes/hip_L_simple_v1_Mirror__Mirror__1.stl" scale="0.001 0.001 0.001"/>
    </geometry>
  </collision>
</link>

<link name="hip_L_simple_v1_Mirror__1">
  <inertial>
    <origin xyz="0.002646937860464965 -0.008154926656354235 0.006021366781819396" rpy="0 0 0"/>
    <mass value="0.010651772367412023"/>
    <inertia ixx="1e-06" iyy="1e-06" izz="1e-06" ixy="-0.0" iyz="-0.0" ixz="-0.0"/>
  </inertial>
  <visual>
    <origin xyz="0.023078 0.051162 -0.012223" rpy="0 0 0"/>
    <geometry>
      <mesh filename="package://dog_assembly_description/meshes/hip_L_simple_v1_Mirror__1.stl" scale="0.001 0.001 0.001"/>
    </geometry>
    <material name="silver"/>
  </visual>
  <collision>
    <origin xyz="0.023078 0.051162 -0.012223" rpy="0 0 0"/>
    <geometry>
      <mesh filename="package://dog_assembly_description/meshes/hip_L_simple_v1_Mirror__1.stl" scale="0.001 0.001 0.001"/>
    </geometry>
  </collision>
</link>

<link name="left_leg_simplified_v2_1">
  <inertial>
    <origin xyz="-0.0114460521349663 -0.03523148516952591 8.48880076726715e-05" rpy="0 0 0"/>
    <mass value="0.012833816117245277"/>
    <inertia ixx="5e-06" iyy="1e-06" izz="6e-06" ixy="-1e-06" iyz="0.0" ixz="0.0"/>
  </inertial>
  <visual>
    <origin xyz="0.038839 -0.060562 -0.013321" rpy="0 0 0"/>
    <geometry>
      <mesh filename="package://dog_assembly_description/meshes/left_leg_simplified_v2_1.stl" scale="0.001 0.001 0.001"/>
    </geometry>
    <material name="silver"/>
  </visual>
  <collision>
    <origin xyz="0.038839 -0.060562 -0.013321" rpy="0 0 0"/>
    <geometry>
      <mesh filename="package://dog_assembly_description/meshes/left_leg_simplified_v2_1.stl" scale="0.001 0.001 0.001"/>
    </geometry>
  </collision>
</link>

<link name="left_leg_simplified_v2_Mirror__1">
  <inertial>
    <origin xyz="0.010647029661782971 -0.035231468444412606 8.489995842720331e-05" rpy="0 0 0"/>
    <mass value="0.012833810246660365"/>
    <inertia ixx="5e-06" iyy="1e-06" izz="6e-06" ixy="1e-06" iyz="0.0" ixz="-0.0"/>
  </inertial>
  <visual>
    <origin xyz="-0.037722 -0.060562 -0.013254" rpy="0 0 0"/>
    <geometry>
      <mesh filename="package://dog_assembly_description/meshes/left_leg_simplified_v2_Mirror__1.stl" scale="0.001 0.001 0.001"/>
    </geometry>
    <material name="silver"/>
  </visual>
  <collision>
    <origin xyz="-0.037722 -0.060562 -0.013254" rpy="0 0 0"/>
    <geometry>
      <mesh filename="package://dog_assembly_description/meshes/left_leg_simplified_v2_Mirror__1.stl" scale="0.001 0.001 0.001"/>
    </geometry>
  </collision>
</link>

<link name="left_leg_simplified_v2_Mirror__2">
  <inertial>
    <origin xyz="0.010647029661783013 -0.03523211157862626 8.489995842720331e-05" rpy="0 0 0"/>
    <mass value="0.012833810246660365"/>
    <inertia ixx="5e-06" iyy="1e-06" izz="6e-06" ixy="1e-06" iyz="0.0" ixz="-0.0"/>
  </inertial>
  <visual>
    <origin xyz="-0.037722 0.060562 -0.013254" rpy="0 0 0"/>
    <geometry>
      <mesh filename="package://dog_assembly_description/meshes/left_leg_simplified_v2_Mirror__2.stl" scale="0.001 0.001 0.001"/>
    </geometry>
    <material name="silver"/>
  </visual>
  <collision>
    <origin xyz="-0.037722 0.060562 -0.013254" rpy="0 0 0"/>
    <geometry>
      <mesh filename="package://dog_assembly_description/meshes/left_leg_simplified_v2_Mirror__2.stl" scale="0.001 0.001 0.001"/>
    </geometry>
  </collision>
</link>

<link name="left_leg_simplified_v2__1__1">
  <inertial>
    <origin xyz="-0.0114460521349663 -0.035232128303739556 8.488800767265763e-05" rpy="0 0 0"/>
    <mass value="0.012833816117245277"/>
    <inertia ixx="5e-06" iyy="1e-06" izz="6e-06" ixy="-1e-06" iyz="0.0" ixz="0.0"/>
  </inertial>
  <visual>
    <origin xyz="0.038839 0.060562 -0.013321" rpy="0 0 0"/>
    <geometry>
      <mesh filename="package://dog_assembly_description/meshes/left_leg_simplified_v2__1__1.stl" scale="0.001 0.001 0.001"/>
    </geometry>
    <material name="silver"/>
  </visual>
  <collision>
    <origin xyz="0.038839 0.060562 -0.013321" rpy="0 0 0"/>
    <geometry>
      <mesh filename="package://dog_assembly_description/meshes/left_leg_simplified_v2__1__1.stl" scale="0.001 0.001 0.001"/>
    </geometry>
  </collision>
</link>

<link name="lower_leg_L_simplified_v1_Mirror__1">
  <inertial>
    <origin xyz="-0.0004086103204771624 0.009896117257288619 -9.70420715518637e-06" rpy="0 0 0"/>
    <mass value="0.001771949492845006"/>
    <inertia ixx="0.0" iyy="0.0" izz="0.0" ixy="0.0" iyz="-0.0" ixz="-0.0"/>
  </inertial>
  <visual>
    <origin xyz="-0.036972 -0.009462 -0.013404" rpy="0 0 0"/>
    <geometry>
      <mesh filename="package://dog_assembly_description/meshes/lower_leg_L_simplified_v1_Mirror__1.stl" scale="0.001 0.001 0.001"/>
    </geometry>
    <material name="silver"/>
  </visual>
  <collision>
    <origin xyz="-0.036972 -0.009462 -0.013404" rpy="0 0 0"/>
    <geometry>
      <mesh filename="package://dog_assembly_description/meshes/lower_leg_L_simplified_v1_Mirror__1.stl" scale="0.001 0.001 0.001"/>
    </geometry>
  </collision>
</link>

<link name="lower_leg_L_simplified_v1_Mirror__2">
  <inertial>
    <origin xyz="-0.00040861032047719015 0.009895474123074968 -9.704207155175962e-06" rpy="0 0 0"/>
    <mass value="0.001771949492845006"/>
    <inertia ixx="0.0" iyy="0.0" izz="0.0" ixy="0.0" iyz="-0.0" ixz="-0.0"/>
  </inertial>
  <visual>
    <origin xyz="-0.036972 0.111662 -0.013404" rpy="0 0 0"/>
    <geometry>
      <mesh filename="package://dog_assembly_description/meshes/lower_leg_L_simplified_v1_Mirror__2.stl" scale="0.001 0.001 0.001"/>
    </geometry>
    <material name="silver"/>
  </visual>
  <collision>
    <origin xyz="-0.036972 0.111662 -0.013404" rpy="0 0 0"/>
    <geometry>
      <mesh filename="package://dog_assembly_description/meshes/lower_leg_L_simplified_v1_Mirror__2.stl" scale="0.001 0.001 0.001"/>
    </geometry>
  </collision>
</link>

<link name="lower_leg_L_simplified_v1__1__1">
  <inertial>
    <origin xyz="0.0004095849166926846 0.009895474123074968 -9.716909047385869e-06" rpy="0 0 0"/>
    <mass value="0.0017719494928450056"/>
    <inertia ixx="0.0" iyy="0.0" izz="0.0" ixy="-0.0" iyz="-0.0" ixz="0.0"/>
  </inertial>
  <visual>
    <origin xyz="0.038889 0.111662 -0.013471" rpy="0 0 0"/>
    <geometry>
      <mesh filename="package://dog_assembly_description/meshes/lower_leg_L_simplified_v1__1__1.stl" scale="0.001 0.001 0.001"/>
    </geometry>
    <material name="silver"/>
  </visual>
  <collision>
    <origin xyz="0.038889 0.111662 -0.013471" rpy="0 0 0"/>
    <geometry>
      <mesh filename="package://dog_assembly_description/meshes/lower_leg_L_simplified_v1__1__1.stl" scale="0.001 0.001 0.001"/>
    </geometry>
  </collision>
</link>

<link name="lower_leg_L_simplified_v1_1">
  <inertial>
    <origin xyz="0.0004095849166926846 0.009896117257288633 -9.716909047396277e-06" rpy="0 0 0"/>
    <mass value="0.0017719494928450056"/>
    <inertia ixx="0.0" iyy="0.0" izz="0.0" ixy="-0.0" iyz="-0.0" ixz="0.0"/>
  </inertial>
  <visual>
    <origin xyz="0.038889 -0.009462 -0.013471" rpy="0 0 0"/>
    <geometry>
      <mesh filename="package://dog_assembly_description/meshes/lower_leg_L_simplified_v1_1.stl" scale="0.001 0.001 0.001"/>
    </geometry>
    <material name="silver"/>
  </visual>
  <collision>
    <origin xyz="0.038889 -0.009462 -0.013471" rpy="0 0 0"/>
    <geometry>
      <mesh filename="package://dog_assembly_description/meshes/lower_leg_L_simplified_v1_1.stl" scale="0.001 0.001 0.001"/>
    </geometry>
  </collision>
</link>

<joint name="Revolute 1" type="revolute">
  <origin xyz="-0.023078 0.051162 0.012223" rpy="0 0 0"/>
  <parent link="base_link"/>
  <child link="hip_L_simple_v2_1"/>
  <axis xyz="0.0 -1.0 0.0"/>
  <limit upper="2.617994" lower="-0.523599" effort="100" velocity="100"/>
</joint>

<joint name="Revolute 2" type="revolute">
  <origin xyz="0.021962 0.051162 0.012156" rpy="0 0 0"/>
  <parent link="base_link"/>
  <child link="hip_L_simple_v1_Mirror___1__1"/>
  <axis xyz="0.0 1.0 -0.0"/>
  <limit upper="2.617994" lower="-0.523599" effort="100" velocity="100"/>
</joint>

<joint name="Revolute 3" type="revolute">
  <origin xyz="0.021962 -0.051162 0.012156" rpy="0 0 0"/>
  <parent link="base_link"/>
  <child link="hip_L_simple_v1_Mirror__Mirror__1"/>
  <axis xyz="-0.0 1.0 0.0"/>
  <limit upper="2.617994" lower="-0.523599" effort="100" velocity="100"/>
</joint>

<joint name="Revolute 4" type="revolute">
  <origin xyz="-0.023078 -0.051162 0.012223" rpy="0 0 0"/>
  <parent link="base_link"/>
  <child link="hip_L_simple_v1_Mirror__1"/>
  <axis xyz="-0.0 -1.0 -0.0"/>
  <limit upper="2.617994" lower="-0.523599" effort="100" velocity="100"/>
</joint>

<joint name="Revolute 5" type="revolute">
  <origin xyz="-0.015761 0.0094 0.001098" rpy="0 0 0"/>
  <parent link="hip_L_simple_v2_1"/>
  <child link="left_leg_simplified_v2_1"/>
  <axis xyz="-1.0 0.0 -0.0"/>
  <limit upper="0.523599" lower="0.0" effort="100" velocity="100"/>
</joint>

<joint name="Revolute 6" type="revolute">
  <origin xyz="0.01576 0.0094 0.001098" rpy="0 0 0"/>
  <parent link="hip_L_simple_v1_Mirror___1__1"/>
  <child link="left_leg_simplified_v2_Mirror__1"/>
  <axis xyz="-1.0 -0.0 0.0"/>
  <limit upper="0.523599" lower="-2.617994" effort="100" velocity="100"/>
</joint>

<joint name="Revolute 7" type="revolute">
  <origin xyz="0.01576 -0.0094 0.001098" rpy="0 0 0"/>
  <parent link="hip_L_simple_v1_Mirror__Mirror__1"/>
  <child link="left_leg_simplified_v2_Mirror__2"/>
  <axis xyz="1.0 -0.0 -0.0"/>
  <limit upper="2.617994" lower="-0.523599" effort="100" velocity="100"/>
</joint>

<joint name="Revolute 8" type="revolute">
  <origin xyz="-0.015761 -0.0094 0.001098" rpy="0 0 0"/>
  <parent link="hip_L_simple_v1_Mirror__1"/>
  <child link="left_leg_simplified_v2__1__1"/>
  <axis xyz="1.0 0.0 0.0"/>
  <limit upper="2.617994" lower="-0.523599" effort="100" velocity="100"/>
</joint>

<joint name="Revolute 10" type="revolute">
  <origin xyz="-0.00075 -0.0511 0.00015" rpy="0 0 0"/>
  <parent link="left_leg_simplified_v2_Mirror__1"/>
  <child link="lower_leg_L_simplified_v1_Mirror__1"/>
  <axis xyz="1.0 0.0 -0.0"/>
  <limit upper="6.283185" lower="3.141593" effort="100" velocity="100"/>
</joint>

<joint name="Revolute 11" type="revolute">
  <origin xyz="-0.00075 -0.0511 0.00015" rpy="0 0 0"/>
  <parent link="left_leg_simplified_v2_Mirror__2"/>
  <child link="lower_leg_L_simplified_v1_Mirror__2"/>
  <axis xyz="1.0 0.0 -0.0"/>
  <limit upper="6.283185" lower="3.141593" effort="100" velocity="100"/>
</joint>

<joint name="Revolute 12" type="revolute">
  <origin xyz="-5e-05 -0.0511 0.00015" rpy="0 0 0"/>
  <parent link="left_leg_simplified_v2__1__1"/>
  <child link="lower_leg_L_simplified_v1__1__1"/>
  <axis xyz="1.0 -0.0 0.0"/>
  <limit upper="6.283185" lower="3.141593" effort="100" velocity="100"/>
</joint>

<joint name="Revolute 9" type="revolute">
  <origin xyz="-5e-05 -0.0511 0.00015" rpy="0 0 0"/>
  <parent link="left_leg_simplified_v2_1"/>
  <child link="lower_leg_L_simplified_v1_1"/>
  <axis xyz="1.0 -0.0 0.0"/>
  <limit upper="6.283185" lower="3.141593" effort="100" velocity="100"/>
</joint>

</robot>
